{"errorMessage":"Lambda process returned error status code: 1. Result: {\"errorType\":\"NetworkingError\",\"errorMessage\":\"connect ECONNREFUSED 127.0.0.1:4566\"}. Output:\n\u001b[32mSTART RequestId: 9f46002d-85e4-18f4-974b-79804fd836ab Version: $LATEST\u001b[0m\n2021-03-20T09:43:22.244Z\t9f46002d-85e4-18f4-974b-79804fd836ab\tINFO\t{\"title\":\"Hello\",\"task\":\"world\"}\n2021-03-20T09:43:43.368Z\t9f46002d-85e4-18f4-974b-79804fd836ab\tERROR\tInvoke Error \t{\"errorType\":\"NetworkingError\",\"errorMessage\":\"connect ECONNREFUSED 127.0.0.1:4566\",\"code\":\"NetworkingError\",\"message\":\"connect ECONNREFUSED 127.0.0.1:4566\",\"errno\":\"ECONNREFUSED\",\"syscall\":\"connect\",\"address\":\"127.0.0.1\",\"port\":4566,\"region\":\"us-west-2\",\"hostname\":\"localhost\",\"retryable\":true,\"time\":\"2021-03-20T09:43:43.366Z\",\"stack\":[\"Error: connect ECONNREFUSED 127.0.0.1:4566\",\"    at TCPConnectWrap.afterConnect [as oncomplete] (net.js:1144:16)\"]}\n\u001b[32mEND RequestId: 9f46002d-85e4-18f4-974b-79804fd836ab\u001b[0m\n\u001b[32mREPORT RequestId: 9f46002d-85e4-18f4-974b-79804fd836ab\tInit Duration: 318.34 ms\tDuration: 3000.00 ms\tBilled Duration: 3000 ms\tMemory Size: 1536 MB\tMax Memory Used: 56 MB\t\u001b[0m","errorType":"InvocationException","stackTrace":["  File \"/opt/code/localstack/localstack/services/awslambda/lambda_api.py\", line 574, in run_lambda\n    result = LAMBDA_EXECUTOR.execute(func_arn, func_details, event, context=context,\n","  File \"/opt/code/localstack/localstack/services/awslambda/lambda_executors.py\", line 176, in execute\n    return do_execute()\n","  File \"/opt/code/localstack/localstack/services/awslambda/lambda_executors.py\", line 168, in do_execute\n    return _run(func_arn=func_arn)\n","  File \"/opt/code/localstack/localstack/utils/cloudwatch/cloudwatch_util.py\", line 149, in wrapped\n    raise e\n","  File \"/opt/code/localstack/localstack/utils/cloudwatch/cloudwatch_util.py\", line 145, in wrapped\n    result = func(*args, **kwargs)\n","  File \"/opt/code/localstack/localstack/services/awslambda/lambda_executors.py\", line 159, in _run\n    raise e\n","  File \"/opt/code/localstack/localstack/services/awslambda/lambda_executors.py\", line 147, in _run\n    result = self._execute(func_arn, func_details, event, context, version)\n","  File \"/opt/code/localstack/localstack/services/awslambda/lambda_executors.py\", line 325, in _execute\n    result = self.run_lambda_executor(cmd, stdin, env_vars=environment, func_details=func_details)\n","  File \"/opt/code/localstack/localstack/services/awslambda/lambda_executors.py\", line 231, in run_lambda_executor\n    raise InvocationException('Lambda process returned error status code: %s. Result: %s. Output:\\n%s' %\n"]}
