{"errorMessage":"Lambda process returned error status code: 1. Result: {\"errorType\":\"CredentialsError\",\"errorMessage\":\"Missing credentials in config, if using AWS_CONFIG_FILE, set AWS_SDK_LOAD_CONFIG=1\"}. Output:\n\u001b[32mSTART RequestId: 171b7193-1ed9-1afe-0f12-b5393617557c Version: $LATEST\u001b[0m\n2021-03-17T18:43:08.338Z\t171b7193-1ed9-1afe-0f12-b5393617557c\tINFO\t{\"task\":\"all\"}\n2021-03-17T18:43:16.901Z\t171b7193-1ed9-1afe-0f12-b5393617557c\tERROR\tInvoke Error \t{\"errorType\":\"CredentialsError\",\"errorMessage\":\"Missing credentials in config, if using AWS_CONFIG_FILE, set AWS_SDK_LOAD_CONFIG=1\",\"code\":\"CredentialsError\",\"message\":\"Missing credentials in config, if using AWS_CONFIG_FILE, set AWS_SDK_LOAD_CONFIG=1\",\"time\":\"2021-03-17T18:43:16.891Z\",\"retryable\":true,\"originalError\":{\"message\":\"Could not load credentials from any providers\",\"code\":\"CredentialsError\",\"time\":\"2021-03-17T18:43:16.891Z\",\"retryable\":true,\"originalError\":{\"message\":\"EC2 Metadata roleName request returned error\",\"code\":\"TimeoutError\",\"time\":\"2021-03-17T18:43:16.890Z\",\"retryable\":true,\"originalError\":{\"message\":\"Socket timed out without establishing a connection\",\"code\":\"TimeoutError\",\"time\":\"2021-03-17T18:43:16.890Z\",\"retryable\":true}}},\"stack\":[\"CredentialsError: Missing credentials in config, if using AWS_CONFIG_FILE, set AWS_SDK_LOAD_CONFIG=1\",\"    at Timeout.connectTimeout [as _onTimeout] (/var/runtime/node_modules/aws-sdk/lib/http/node.js:69:15)\",\"    at listOnTimeout (internal/timers.js:554:17)\",\"    at processTimers (internal/timers.js:497:7)\"]}\n\u001b[32mEND RequestId: 171b7193-1ed9-1afe-0f12-b5393617557c\u001b[0m\n\u001b[32mREPORT RequestId: 171b7193-1ed9-1afe-0f12-b5393617557c\tInit Duration: 591.01 ms\tDuration: 3000.00 ms\tBilled Duration: 3000 ms\tMemory Size: 1536 MB\tMax Memory Used: 55 MB\t\u001b[0m","errorType":"InvocationException","stackTrace":["  File \"/opt/code/localstack/localstack/services/awslambda/lambda_api.py\", line 574, in run_lambda\n    result = LAMBDA_EXECUTOR.execute(func_arn, func_details, event, context=context,\n","  File \"/opt/code/localstack/localstack/services/awslambda/lambda_executors.py\", line 176, in execute\n    return do_execute()\n","  File \"/opt/code/localstack/localstack/services/awslambda/lambda_executors.py\", line 168, in do_execute\n    return _run(func_arn=func_arn)\n","  File \"/opt/code/localstack/localstack/utils/cloudwatch/cloudwatch_util.py\", line 149, in wrapped\n    raise e\n","  File \"/opt/code/localstack/localstack/utils/cloudwatch/cloudwatch_util.py\", line 145, in wrapped\n    result = func(*args, **kwargs)\n","  File \"/opt/code/localstack/localstack/services/awslambda/lambda_executors.py\", line 159, in _run\n    raise e\n","  File \"/opt/code/localstack/localstack/services/awslambda/lambda_executors.py\", line 147, in _run\n    result = self._execute(func_arn, func_details, event, context, version)\n","  File \"/opt/code/localstack/localstack/services/awslambda/lambda_executors.py\", line 325, in _execute\n    result = self.run_lambda_executor(cmd, stdin, env_vars=environment, func_details=func_details)\n","  File \"/opt/code/localstack/localstack/services/awslambda/lambda_executors.py\", line 231, in run_lambda_executor\n    raise InvocationException('Lambda process returned error status code: %s. Result: %s. Output:\\n%s' %\n"]}
