{"errorMessage":"Lambda process returned error status code: 1. Result: {\"errorMessage\":\"2021-03-17T17:59:17.65Z d11b2b62-16e1-1e1d-0516-0f3583095674 Task timed out after 3.00 seconds\"}. Output:\n\u001b[32mSTART RequestId: d11b2b62-16e1-1e1d-0516-0f3583095674 Version: $LATEST\u001b[0m\n2021-03-17T17:59:08.798Z\td11b2b62-16e1-1e1d-0516-0f3583095674\tINFO\t{}\n2021-03-17T17:59:08.803Z\td11b2b62-16e1-1e1d-0516-0f3583095674\tINFO\tPut Starting\n2021-03-17T17:59:17.644Z\td11b2b62-16e1-1e1d-0516-0f3583095674\tERROR\tError [CredentialsError]: Missing credentials in config, if using AWS_CONFIG_FILE, set AWS_SDK_LOAD_CONFIG=1\n    at Timeout.connectTimeout [as _onTimeout] (/var/runtime/node_modules/aws-sdk/lib/http/node.js:69:15)\n    at listOnTimeout (internal/timers.js:554:17)\n    at processTimers (internal/timers.js:497:7) {\n  code: 'CredentialsError',\n  time: 2021-03-17T17:59:17.629Z,\n  retryable: true,\n  originalError: {\n    message: 'Could not load credentials from any providers',\n    code: 'CredentialsError',\n    time: 2021-03-17T17:59:17.628Z,\n    retryable: true,\n    originalError: {\n      message: 'EC2 Metadata roleName request returned error',\n      code: 'TimeoutError',\n      time: 2021-03-17T17:59:17.627Z,\n      retryable: true,\n      originalError: [Object]\n    }\n  }\n}\n\u001b[32mEND RequestId: d11b2b62-16e1-1e1d-0516-0f3583095674\u001b[0m\n\u001b[32mREPORT RequestId: d11b2b62-16e1-1e1d-0516-0f3583095674\tInit Duration: 911.26 ms\tDuration: 3000.00 ms\tBilled Duration: 3000 ms\tMemory Size: 1536 MB\tMax Memory Used: 55 MB\t\u001b[0m","errorType":"InvocationException","stackTrace":["  File \"/opt/code/localstack/localstack/services/awslambda/lambda_api.py\", line 574, in run_lambda\n    result = LAMBDA_EXECUTOR.execute(func_arn, func_details, event, context=context,\n","  File \"/opt/code/localstack/localstack/services/awslambda/lambda_executors.py\", line 176, in execute\n    return do_execute()\n","  File \"/opt/code/localstack/localstack/services/awslambda/lambda_executors.py\", line 168, in do_execute\n    return _run(func_arn=func_arn)\n","  File \"/opt/code/localstack/localstack/utils/cloudwatch/cloudwatch_util.py\", line 149, in wrapped\n    raise e\n","  File \"/opt/code/localstack/localstack/utils/cloudwatch/cloudwatch_util.py\", line 145, in wrapped\n    result = func(*args, **kwargs)\n","  File \"/opt/code/localstack/localstack/services/awslambda/lambda_executors.py\", line 159, in _run\n    raise e\n","  File \"/opt/code/localstack/localstack/services/awslambda/lambda_executors.py\", line 147, in _run\n    result = self._execute(func_arn, func_details, event, context, version)\n","  File \"/opt/code/localstack/localstack/services/awslambda/lambda_executors.py\", line 325, in _execute\n    result = self.run_lambda_executor(cmd, stdin, env_vars=environment, func_details=func_details)\n","  File \"/opt/code/localstack/localstack/services/awslambda/lambda_executors.py\", line 231, in run_lambda_executor\n    raise InvocationException('Lambda process returned error status code: %s. Result: %s. Output:\\n%s' %\n"]}
